<?xml version="1.0" ?>
<!-- =================================================================================== -->
<!-- |    This document was autogenerated by xacro from /home/demulab/catkin_ws/src/tsuzuki_sim_description/urdf/tsuzuki_sim_approximate.urdf.xacro | -->
<!-- |    EDITING THIS FILE BY HAND IS NOT RECOMMENDED                                 | -->
<!-- =================================================================================== -->
<!-- author: nosaka -->
<robot name="tsuzuki_sim">
    <gazebo>
        <plugin filename="libgazebo_ros_control.so" name="ros_control">
            <robotNamespace>/</robotNamespace>
            <robotSimType>gazebo_ros_control/DefaultRobotHWSim</robotSimType>
        </plugin>
        <plugin name="gazebo_ros_control">
            <robotNamespace>/</robotNamespace>
        </plugin>
    </gazebo>
    <!-- setup pedestal related -->
    <gazebo reference="pedestal_link">
        <material>Gazebo/DarkGrey</material>
    </gazebo>
    <!-- setup ensenso_n35 related -->
    <gazebo reference="N35_mounting_frame">
        <material>Gazebo/SkyBlue</material>
    </gazebo>
    <gazebo reference="N35_left_lens_frame">
        <!-- N35_mounting_frame -->
        <sensor name="n35" type="depth">
            <always_on>true</always_on>
            <update_rate>10.0</update_rate>
            <camera>
                <!-- In the gazebo camera plugin, X-axis is set to the front of the camera by default. -->
                <pose>0. 0. 0. 0. -1.57079632679 1.57079632679</pose>
                <horizontal_fov>0.801812880108</horizontal_fov>
                <!-- default: 1.04666667 -->
                <image>
                    <!-- image format_type select from
                 (L8/R8G8B8/B8G8R8/BAYER_RGGB8/BAYER_BGGR8/BAYER_GBRG8/BAYER_GRBG8) -->
                    <format>L8</format>
                    <width>1280</width>
                    <height>1024</height>
                </image>
                <clip>
                    <near>0.05</near>
                    <far>3.0</far>
                </clip>
                <noise>
                    <type>gaussian</type>
                    <mean>0.0</mean>
                    <stddev>0.01</stddev>
                </noise>
            </camera>
            <plugin filename="libgazebo_ros_openni_kinect.so" name="ensenso_n35_controller">
                <cameraName>n35</cameraName>
                <baseline>0.1</baseline>
                <alwaysOn>true</alwaysOn>
                <updateRate>10</updateRate>
                <frameName>N35_left_lens_frame</frameName>
                <!-- N35_mounting_frame -->
                <imageTopicName>/n35/color/image_raw</imageTopicName>
                <cameraInfoTopicName>/n35/color/camera_info</cameraInfoTopicName>
                <depthImageTopicName>/n35/depth/image_raw</depthImageTopicName>
                <depthImageCameraInfoTopicName>/n35/depth/camera_info</depthImageCameraInfoTopicName>
                <pointCloudTopicName>/n35/depth/points</pointCloudTopicName>
                <pointCloudCutoff>0.4</pointCloudCutoff>
                <distortion_k1>0.0</distortion_k1>
                <distortion_k2>0.0</distortion_k2>
                <distortion_k3>0.0</distortion_k3>
                <distortion_t1>0.0</distortion_t1>
                <distortion_t2>0.0</distortion_t2>
                <CxPrime>0</CxPrime>
                <Cx>499.077</Cx>
                <!-- default: 0 -->
                <Cy>511.474</Cy>
                <!-- default: 0 -->
                <focalLength>1509.92479709</focalLength>
                <!-- default: 0 -->
                <hackBaseline>0</hackBaseline>
            </plugin>
        </sensor>
    </gazebo>
    <!-- setup fingers related -->
    <gazebo reference="robotiq_85_left_finger_tip_link">
        <kp>1000000.0</kp>
        <kd>1.0</kd>
        <mu1>1.0</mu1>
        <mu2>1.0</mu2>
        <minDepth>0.001</minDepth>
    </gazebo>
    <gazebo reference="robotiq_85_right_finger_tip_link">
        <kp>1000000.0</kp>
        <kd>1.0</kd>
        <mu1>1.0</mu1>
        <mu2>1.0</mu2>
        <minDepth>0.001</minDepth>
    </gazebo>
    <gazebo reference="tsuzuki_left_finger_tip_link">
        <sensor name="contact_left" type="contact">
            <always_on>true</always_on>
            <update_rate>10</update_rate>
            <contact>
                <collision>tsuzuki_left_finger_tip_link_collision</collision>
            </contact>
            <plugin filename="libgazebo_ros_bumper.so" name="left_finger_gazebo_ros_bumper_controller">
                <alwaysOn>true</alwaysOn>
                <updateRate>10</updateRate>
                <bumperTopicName>/contact_detect_left</bumperTopicName>
                <frameName>world</frameName>
            </plugin>
        </sensor>
    </gazebo>
    <gazebo reference="tsuzuki_left_finger_tip_link">
        <kp>1000000.0</kp>
        <kd>1.0</kd>
        <mu1>10.0</mu1>
        <mu2>10.0</mu2>
        <minDepth>0.001</minDepth>
        <material>Gazebo/Grey</material>
    </gazebo>
    <gazebo reference="tsuzuki_right_finger_tip_link">
        <sensor name="contact_right" type="contact">
            <always_on>true</always_on>
            <update_rate>10</update_rate>
            <contact>
                <collision>tsuzuki_right_finger_tip_link_collision</collision>
            </contact>
            <plugin filename="libgazebo_ros_bumper.so" name="right_finger_gazebo_ros_bumper_controller">
                <alwaysOn>true</alwaysOn>
                <updateRate>10</updateRate>
                <bumperTopicName>/contact_detect_right</bumperTopicName>
                <frameName>world</frameName>
            </plugin>
        </sensor>
    </gazebo>
    <gazebo reference="tsuzuki_right_finger_tip_link">
        <kp>1000000.0</kp>
        <kd>1.0</kd>
        <mu1>10.0</mu1>
        <mu2>10.0</mu2>
        <minDepth>0.001</minDepth>
        <material>Gazebo/Grey</material>
    </gazebo>
    <!-- setup robotiq_coupler related -->
    <gazebo reference="robotiq_coupler">
        <selfCollide>true</selfCollide>
        <mu1>0.9</mu1>
        <mu2>0.9</mu2>
        <material>Gazebo/FlatBlack</material>
    </gazebo>
    <!-- Gazebo FT sensor plugin -->
    <!--gazebo reference="wrist_3_joint">
    <provideFeedback>true</provideFeedback>
  </gazebo>
  <gazebo>
    <plugin name="ft_sensor_plugin" filename="libgazebo_ros_ft_sensor.so">
      <updateRate>250.0</updateRate>
      <gaussianNoise>0.0</gaussianNoise>
      <jointName>wrist_3_joint</jointName>
      <topicName>ft_sensor/raw</topicName>
    </plugin>
  </gazebo-->
    <!-- Gazebo grasping plugin -->
    <!--gazebo>
    <gripper name="gazebo_gripper">
      <grasp_check>
        <attach_steps>2</attach_steps>
        <detach_steps>2</detach_steps>
        <min_contact_count>3</min_contact_count>
      </grasp_check>
      <palm_link>robotiq_85_base_link</palm_link>
      <gripper_link>tsuzuki_left_finger_tip_link</gripper_link>
      <gripper_link>tsuzuki_right_finger_tip_link</gripper_link>
    </gripper>
  </gazebo-->
    <!--gazebo>
    <plugin name="gazebo_grasp_fix" filename="libgazebo_grasp_fix.so">
       <arm>
         <arm_name>gazebo_gripper</arm_name>
         <palm_link>robotiq_85_left_inner_knuckle_link</palm_link>
         <palm_link>robotiq_85_right_inner_knuckle_link</palm_link>
         <gripper_link>robotiq_85_left_finger_tip_link</gripper_link>
         <gripper_link>robotiq_85_right_finger_tip_link</gripper_link>
       </arm>
       <forces_angle_tolerance>100</forces_angle_tolerance>
       <update_rate>4</update_rate>
       <grip_count_threshold>4</grip_count_threshold>
       <max_grip_count>8</max_grip_count>
       <release_tolerance>0.005</release_tolerance>
       <disable_collisions_on_attach>false</disable_collisions_on_attach>
       <contact_topic>__default_topic__</contact_topic>
    </plugin>
  </gazebo-->
    <!-- measured from model -->
    <!--property name="shoulder_height" value="0.089159" /-->
    <!--property name="shoulder_offset" value="0.13585" /-->
    <!-- shoulder_offset - elbow_offset + wrist_1_length = 0.10915 -->
    <!--property name="upper_arm_length" value="0.42500" /-->
    <!--property name="elbow_offset" value="0.1197" /-->
    <!-- CAD measured -->
    <!--property name="forearm_length" value="0.39225" /-->
    <!--property name="wrist_1_length" value="0.093" /-->
    <!-- CAD measured -->
    <!--property name="wrist_2_length" value="0.09465" /-->
    <!-- In CAD this distance is 0.930, but in the spec it is 0.09465 -->
    <!--property name="wrist_3_length" value="0.0823" /-->
    <!-- manually measured -->
    <material name="Ensenso/Blue">
        <color rgba="0.1 0.1 1.0 1.0" />
    </material>
    <link name="ensenso_world" />
    <joint name="ensenso_world_N35_joint" type="fixed">
        <origin rpy="0 0 0" xyz="0 0 0" />
        <parent link="ensenso_world" />
        <child link="N35_mounting_frame" />
    </joint>
    <link name="N35_mounting_frame">
        <visual>
            <!--origin rpy="0. 0. 0." xyz="0. 0. 0." /-->
            <origin rpy="0. 0. 3.141592653589793" xyz="0. 0. 0." />
            <geometry>
                <!--mesh filename="package://tsuzuki_sim_description/meshes/camera/ensenso/N30-602-16.stl"/-->
                <mesh filename="package://tsuzuki_sim_description/meshes/camera/ensenso/N3x.stl" />
            </geometry>
            <material name="Ensenso/Blue" />
        </visual>
        <collision>
            <!--origin rpy="0. 0. 0." xyz="0. 0. 0." /-->
            <origin rpy="0. 0. 3.141592653589793" xyz="0. 0. 0." />
            <geometry>
                <!--mesh filename="package://tsuzuki_sim_description/meshes/camera/ensenso/N30-602-16.stl"/-->
                <mesh filename="package://tsuzuki_sim_description/meshes/camera/ensenso/N3x.stl" />
            </geometry>
        </collision>
        <inertial>
            <origin rpy="0. 0. 0." xyz="0. 0. 0." />
            <mass value="0.65" />
            <inertia ixx="0.001" ixy="0.0" ixz="0.0" iyy="0.001" iyz="0.0" izz="0.001" />
        </inertial>
    </link>
    <!-- Projector -->
    <joint name="N35_projector_joint" type="fixed">
        <parent link="N35_mounting_frame" />
        <child link="N35_projector_lens_frame" />
        <origin rpy=" 0 0 0" xyz="0 0.00 0.05" />
    </joint>
    <link name="N35_projector_lens_frame" />
    <!-- Left lens -->
    <joint name="N35_left_lense_joint" type="fixed">
        <parent link="N35_mounting_frame" />
        <child link="N35_left_lens_frame" />
        <origin rpy=" 0 0 0" xyz="-0.05 0.00 0.05" />
    </joint>
    <link name="N35_left_lens_frame" />
    <!-- Right lens -->
    <joint name="N35_right_lens_joint" type="fixed">
        <parent link="N35_mounting_frame" />
        <child link="N35_right_lens_frame" />
        <origin rpy=" 0 0 0" xyz="0.05 0.00 0.05" />
    </joint>
    <link name="N35_right_lens_frame" />
    <link name="base_link">
        <visual>
            <geometry>
                <mesh filename="package://tsuzuki_sim_description/meshes/ur5/visual/base.dae" />
            </geometry>
            <material name="LightGrey">
                <color rgba="0.7 0.7 0.7 1.0" />
            </material>
        </visual>
        <collision>
            <geometry>
                <mesh filename="package://tsuzuki_sim_description/meshes/ur5/collision/base.stl" />
            </geometry>
        </collision>
        <inertial>
            <mass value="4.0" />
            <origin rpy="0 0 0" xyz="0.0 0.0 0.0" />
            <inertia ixx="0.00443333156" ixy="0.0" ixz="0.0" iyy="0.00443333156" iyz="0.0" izz="0.0072" />
        </inertial>
    </link>
    <joint name="shoulder_pan_joint" type="revolute">
        <parent link="base_link" />
        <child link="shoulder_link" />
        <origin rpy="0.0 0.0 0.0" xyz="0.0 0.0 0.089159" />
        <axis xyz="0 0 1" />
        <limit effort="150.0" lower="-6.283185307179586" upper="6.283185307179586" velocity="3.15" />
        <dynamics damping="0.0" friction="0.0" />
    </joint>
    <link name="shoulder_link">
        <visual>
            <geometry>
                <mesh filename="package://tsuzuki_sim_description/meshes/ur5/visual/shoulder.dae" />
            </geometry>
            <material name="LightGrey">
                <color rgba="0.7 0.7 0.7 1.0" />
            </material>
        </visual>
        <collision>
            <geometry>
                <mesh filename="package://tsuzuki_sim_description/meshes/ur5/collision/shoulder.stl" />
            </geometry>
        </collision>
        <inertial>
            <mass value="3.7" />
            <origin rpy="0 0 0" xyz="0.0 0.0 0.0" />
            <inertia ixx="0.010267495893" ixy="0.0" ixz="0.0" iyy="0.010267495893" iyz="0.0" izz="0.00666" />
        </inertial>
    </link>
    <joint name="shoulder_lift_joint" type="revolute">
        <parent link="shoulder_link" />
        <child link="upper_arm_link" />
        <origin rpy="0.0 1.5707963267948966 0.0" xyz="0.0 0.13585 0.0" />
        <axis xyz="0 1 0" />
        <limit effort="150.0" lower="-6.283185307179586" upper="6.283185307179586" velocity="3.15" />
        <dynamics damping="0.0" friction="0.0" />
    </joint>
    <link name="upper_arm_link">
        <visual>
            <geometry>
                <mesh filename="package://tsuzuki_sim_description/meshes/ur5/visual/upperarm.dae" />
            </geometry>
            <material name="LightGrey">
                <color rgba="0.7 0.7 0.7 1.0" />
            </material>
        </visual>
        <collision>
            <geometry>
                <mesh filename="package://tsuzuki_sim_description/meshes/ur5/collision/upperarm.stl" />
            </geometry>
        </collision>
        <inertial>
            <mass value="8.393" />
            <origin rpy="0 0 0" xyz="0.0 0.0 0.28" />
            <inertia ixx="0.22689067591036005" ixy="0.0" ixz="0.0" iyy="0.22689067591036005" iyz="0.0" izz="0.0151074" />
        </inertial>
    </link>
    <joint name="elbow_joint" type="revolute">
        <parent link="upper_arm_link" />
        <child link="forearm_link" />
        <origin rpy="0.0 0.0 0.0" xyz="0.0 -0.1197 0.425" />
        <axis xyz="0 1 0" />
        <limit effort="150.0" lower="-3.141592653589793" upper="3.141592653589793" velocity="3.15" />
        <dynamics damping="0.0" friction="0.0" />
    </joint>
    <link name="forearm_link">
        <visual>
            <geometry>
                <mesh filename="package://tsuzuki_sim_description/meshes/ur5/visual/forearm.dae" />
            </geometry>
            <material name="LightGrey">
                <color rgba="0.7 0.7 0.7 1.0" />
            </material>
        </visual>
        <collision>
            <geometry>
                <mesh filename="package://tsuzuki_sim_description/meshes/ur5/collision/forearm.stl" />
            </geometry>
        </collision>
        <inertial>
            <mass value="2.275" />
            <origin rpy="0 0 0" xyz="0.0 0.0 0.25" />
            <inertia ixx="0.04944331355599999" ixy="0.0" ixz="0.0" iyy="0.04944331355599999" iyz="0.0" izz="0.004095" />
        </inertial>
    </link>
    <joint name="wrist_1_joint" type="revolute">
        <parent link="forearm_link" />
        <child link="wrist_1_link" />
        <origin rpy="0.0 1.5707963267948966 0.0" xyz="0.0 0.0 0.39225" />
        <axis xyz="0 1 0" />
        <limit effort="28.0" lower="-6.283185307179586" upper="6.283185307179586" velocity="3.2" />
        <dynamics damping="0.0" friction="0.0" />
    </joint>
    <link name="wrist_1_link">
        <visual>
            <geometry>
                <mesh filename="package://tsuzuki_sim_description/meshes/ur5/visual/wrist1.dae" />
            </geometry>
            <material name="LightGrey">
                <color rgba="0.7 0.7 0.7 1.0" />
            </material>
        </visual>
        <collision>
            <geometry>
                <mesh filename="package://tsuzuki_sim_description/meshes/ur5/collision/wrist1.stl" />
            </geometry>
        </collision>
        <inertial>
            <mass value="1.219" />
            <origin rpy="0 0 0" xyz="0.0 0.0 0.0" />
            <inertia ixx="0.11117275553087999" ixy="0.0" ixz="0.0" iyy="0.11117275553087999" iyz="0.0" izz="0.21942" />
        </inertial>
    </link>
    <joint name="wrist_2_joint" type="revolute">
        <parent link="wrist_1_link" />
        <child link="wrist_2_link" />
        <origin rpy="0.0 0.0 0.0" xyz="0.0 0.093 0.0" />
        <axis xyz="0 0 1" />
        <limit effort="28.0" lower="-6.283185307179586" upper="6.283185307179586" velocity="3.2" />
        <dynamics damping="0.0" friction="0.0" />
    </joint>
    <link name="wrist_2_link">
        <visual>
            <geometry>
                <mesh filename="package://tsuzuki_sim_description/meshes/ur5/visual/wrist2.dae" />
            </geometry>
            <material name="LightGrey">
                <color rgba="0.7 0.7 0.7 1.0" />
            </material>
        </visual>
        <collision>
            <geometry>
                <mesh filename="package://tsuzuki_sim_description/meshes/ur5/collision/wrist2.stl" />
            </geometry>
        </collision>
        <inertial>
            <mass value="1.219" />
            <origin rpy="0 0 0" xyz="0.0 0.0 0.0" />
            <inertia ixx="0.11117275553087999" ixy="0.0" ixz="0.0" iyy="0.11117275553087999" iyz="0.0" izz="0.21942" />
        </inertial>
    </link>
    <joint name="wrist_3_joint" type="revolute">
        <parent link="wrist_2_link" />
        <child link="wrist_3_link" />
        <origin rpy="0.0 0.0 0.0" xyz="0.0 0.0 0.09465" />
        <axis xyz="0 1 0" />
        <limit effort="28.0" lower="-6.283185307179586" upper="6.283185307179586" velocity="3.2" />
        <dynamics damping="0.0" friction="0.0" />
    </joint>
    <link name="wrist_3_link">
        <visual>
            <geometry>
                <mesh filename="package://tsuzuki_sim_description/meshes/ur5/visual/wrist3.dae" />
            </geometry>
            <material name="LightGrey">
                <color rgba="0.7 0.7 0.7 1.0" />
            </material>
        </visual>
        <collision>
            <geometry>
                <mesh filename="package://tsuzuki_sim_description/meshes/ur5/collision/wrist3.stl" />
            </geometry>
        </collision>
        <inertial>
            <mass value="0.1879" />
            <origin rpy="0 0 0" xyz="0.0 0.0 0.0" />
            <inertia ixx="0.017136473145408" ixy="0.0" ixz="0.0" iyy="0.017136473145408" iyz="0.0" izz="0.033822" />
        </inertial>
    </link>
    <joint name="ee_fixed_joint" type="fixed">
        <parent link="wrist_3_link" />
        <child link="ee_link" />
        <origin rpy="0.0 0.0 1.5707963267948966" xyz="0.0 0.0823 0.0" />
    </joint>
    <link name="ee_link">
        <collision>
            <geometry>
                <box size="0.01 0.01 0.01" />
            </geometry>
            <origin rpy="0 0 0" xyz="-0.01 0 0" />
        </collision>
        <inertial>
            <mass value="0.1" />
            <origin xyz="0 0 0" rpy="0 0 0" />
            <inertia ixx="0.03" iyy="0.03" izz="0.03" ixy="0.0" ixz="0.0" iyz="0.0" />
        </inertial>
    </link>
    <transmission name="shoulder_pan_trans">
        <type>transmission_interface/SimpleTransmission</type>
        <joint name="shoulder_pan_joint">
            <hardwareInterface>hardware_interface/PositionJointInterface</hardwareInterface>
        </joint>
        <actuator name="shoulder_pan_motor">
            <mechanicalReduction>1</mechanicalReduction>
            <hardwareInterface>hardware_interface/PositionJointInterface</hardwareInterface>
        </actuator>
    </transmission>
    <transmission name="shoulder_lift_trans">
        <type>transmission_interface/SimpleTransmission</type>
        <joint name="shoulder_lift_joint">
            <hardwareInterface>hardware_interface/PositionJointInterface</hardwareInterface>
        </joint>
        <actuator name="shoulder_lift_motor">
            <mechanicalReduction>1</mechanicalReduction>
            <hardwareInterface>hardware_interface/PositionJointInterface</hardwareInterface>
        </actuator>
    </transmission>
    <transmission name="elbow_trans">
        <type>transmission_interface/SimpleTransmission</type>
        <joint name="elbow_joint">
            <hardwareInterface>hardware_interface/PositionJointInterface</hardwareInterface>
        </joint>
        <actuator name="elbow_motor">
            <mechanicalReduction>1</mechanicalReduction>
            <hardwareInterface>hardware_interface/PositionJointInterface</hardwareInterface>
        </actuator>
    </transmission>
    <transmission name="wrist_1_trans">
        <type>transmission_interface/SimpleTransmission</type>
        <joint name="wrist_1_joint">
            <hardwareInterface>hardware_interface/PositionJointInterface</hardwareInterface>
        </joint>
        <actuator name="wrist_1_motor">
            <mechanicalReduction>1</mechanicalReduction>
            <hardwareInterface>hardware_interface/PositionJointInterface</hardwareInterface>
        </actuator>
    </transmission>
    <transmission name="wrist_2_trans">
        <type>transmission_interface/SimpleTransmission</type>
        <joint name="wrist_2_joint">
            <hardwareInterface>hardware_interface/PositionJointInterface</hardwareInterface>
        </joint>
        <actuator name="wrist_2_motor">
            <mechanicalReduction>1</mechanicalReduction>
            <hardwareInterface>hardware_interface/PositionJointInterface</hardwareInterface>
        </actuator>
    </transmission>
    <transmission name="wrist_3_trans">
        <type>transmission_interface/SimpleTransmission</type>
        <joint name="wrist_3_joint">
            <hardwareInterface>hardware_interface/PositionJointInterface</hardwareInterface>
        </joint>
        <actuator name="wrist_3_motor">
            <mechanicalReduction>1</mechanicalReduction>
            <hardwareInterface>hardware_interface/PositionJointInterface</hardwareInterface>
        </actuator>
    </transmission>
    <!-- nothing to do here at the moment -->
    <!--gazebo reference="${prefix}shoulder_link">
      <selfCollide>true</selfCollide>
    </gazebo>
    <gazebo reference="${prefix}upper_arm_link">
      <selfCollide>true</selfCollide>
    </gazebo>
    <gazebo reference="${prefix}forearm_link">
      <selfCollide>true</selfCollide>
    </gazebo>
    <gazebo reference="${prefix}wrist_1_link">
      <selfCollide>true</selfCollide>
    </gazebo>
    <gazebo reference="${prefix}wrist_3_link">
      <selfCollide>true</selfCollide>
    </gazebo>
    <gazebo reference="${prefix}wrist_2_link">
      <selfCollide>true</selfCollide>
    </gazebo>
    <gazebo reference="${prefix}ee_link">
      <selfCollide>true</selfCollide>
    </gazebo-->
    <!-- ROS base_link to UR 'Base' Coordinates transform -->
    <link name="base" />
    <joint name="base_link-base_fixed_joint" type="fixed">
        <!-- NOTE: this rotation is only needed as long as base_link itself is
                 not corrected wrt the real robot (ie: rotated over 180
                 degrees)
      -->
        <origin rpy="0 0 -3.141592653589793" xyz="0 0 0" />
        <parent link="base_link" />
        <child link="base" />
    </joint>
    <!-- Frame coincident with all-zeros TCP on UR controller -->
    <link name="tool0" />
    <joint name="wrist_3_link-tool0_fixed_joint" type="fixed">
        <origin rpy="-1.5707963267948966 0 0" xyz="0 0.0823 0" />
        <parent link="wrist_3_link" />
        <child link="tool0" />
    </joint>
    <joint name="robotiq_85_base_joint" type="fixed">
        <parent link="robotiq_coupler" />
        <child link="robotiq_85_base_link" />
        <origin rpy="0.0 -1.56 0" xyz="0.0 0.0 0.0" />
        <origin rpy="0 -1.5707963267948966 3.141592653589793" xyz="0 0 0.184" />
    </joint>
    <link name="robotiq_85_base_link">
        <visual>
            <geometry>
                <mesh filename="package://tsuzuki_sim_description/meshes/robotiq_85_gripper/visual/robotiq_85_base_link.dae" />
            </geometry>
        </visual>
        <collision>
            <geometry>
                <mesh filename="package://tsuzuki_sim_description/meshes/robotiq_85_gripper/collision/robotiq_85_base_link.stl" />
            </geometry>
        </collision>
        <inertial>
            <mass value="0.636951" />
            <origin xyz="0.031885 -0.000007 0.000000" rpy="0 0 0" />
            <inertia ixx="0.013324" ixy="-0.000005" ixz="0.000000" iyx="-0.000005" iyy="0.017687" iyz="0.000000" izx="0.000000" izy="0.000000" izz="0.019858" />
            <!--inertia ixx="0.000380" ixy="0.000000" ixz="0.000000"
                 iyx="0.000000" iyy="0.001110" iyz="0.000000"
                 izx="0.000000" izy="0.000000" izz="0.001171" /-->
        </inertial>
    </link>
    <joint name="robotiq_85_left_knuckle_joint" type="revolute">
        <parent link="robotiq_85_base_link" />
        <child link="robotiq_85_left_knuckle_link" />
        <axis xyz="0 0 1" />
        <origin rpy="3.141592653589793 0.0 0.0" xyz="0.05490451627 0.03060114443 0.0" />
        <limit effort="1000" lower="0.0" upper="0.80285" velocity="0.5" />
        <dynamics damping="0.1" />
    </joint>
    <joint name="robotiq_85_right_knuckle_joint" type="continuous">
        <parent link="robotiq_85_base_link" />
        <child link="robotiq_85_right_knuckle_link" />
        <axis xyz="0 0 1" />
        <origin rpy="0.0 0.0 0.0" xyz="0.05490451627 -0.03060114443 0.0" />
        <limit effort="1000" lower="-3.14" upper="3.14" velocity="100.0" />
        <dynamics damping="0.1" />
        <mimic joint="robotiq_85_left_knuckle_joint" />
    </joint>
    <link name="robotiq_85_left_knuckle_link">
        <visual>
            <geometry>
                <mesh filename="package://tsuzuki_sim_description/meshes/robotiq_85_gripper/visual/robotiq_85_knuckle_link.dae" />
            </geometry>
        </visual>
        <collision>
            <geometry>
                <mesh filename="package://tsuzuki_sim_description/meshes/robotiq_85_gripper/collision/robotiq_85_knuckle_link.stl" />
            </geometry>
        </collision>
        <inertial>
            <mass value="0.018491" />
            <origin xyz="0.000926 -0.017947 0.0" rpy="0 0 0" />
            <inertia ixx="0.000128" ixy="0.000008" ixz="0.000000" iyx="0.000008" iyy="0.000025" iyz="0.000000" izx="0.000000" izy="0.000000" izz="0.000138" />
            <!--inertia ixx="0.000009"  ixy="-0.000001" ixz="0.000000"
                 iyx="-0.000001" iyy="0.000001"  iyz="0.000000"
                 izx="0.000000"  izy="0.000000"  izz="0.000010" /-->
        </inertial>
    </link>
    <link name="robotiq_85_right_knuckle_link">
        <visual>
            <geometry>
                <mesh filename="package://tsuzuki_sim_description/meshes/robotiq_85_gripper/visual/robotiq_85_knuckle_link.dae" />
            </geometry>
        </visual>
        <collision>
            <geometry>
                <mesh filename="package://tsuzuki_sim_description/meshes/robotiq_85_gripper/collision/robotiq_85_knuckle_link.stl" />
            </geometry>
        </collision>
        <inertial>
            <mass value="0.018491" />
            <origin xyz="0.000926 -0.017947 0.0" rpy="0 0 0" />
            <inertia ixx="0.000128" ixy="0.000008" ixz="0.000000" iyx="0.000008" iyy="0.000025" iyz="0.000000" izx="0.000000" izy="0.000000" izz="0.000138" />
            <!--inertia ixx="0.000009"  ixy="-0.000001" ixz="0.000000"
                 iyx="-0.000001" iyy="0.000001"  iyz="0.000000"
                 izx="0.000000"  izy="0.000000"  izz="0.000010" /-->
        </inertial>
    </link>
    <joint name="robotiq_85_left_finger_joint" type="fixed">
        <parent link="robotiq_85_left_knuckle_link" />
        <child link="robotiq_85_left_finger_link" />
        <origin rpy="0 0 0" xyz="-0.00408552455 -0.03148604435 0.0" />
    </joint>
    <joint name="robotiq_85_right_finger_joint" type="fixed">
        <parent link="robotiq_85_right_knuckle_link" />
        <child link="robotiq_85_right_finger_link" />
        <origin rpy="0 0 0" xyz="-0.00408552455 -0.03148604435 0.0" />
    </joint>
    <link name="robotiq_85_left_finger_link">
        <visual>
            <geometry>
                <mesh filename="package://tsuzuki_sim_description/meshes/robotiq_85_gripper/visual/robotiq_85_finger_link.dae" />
            </geometry>
        </visual>
        <collision>
            <geometry>
                <mesh filename="package://tsuzuki_sim_description/meshes/robotiq_85_gripper/collision/robotiq_85_finger_link.stl" />
            </geometry>
        </collision>
        <inertial>
            <mass value="0.027309" />
            <origin xyz="0.021401 -0.002777 0.0" rpy="0 0 0" />
            <inertia ixx="0.000086" ixy="0.000030" ixz="0.000000" iyx="0.000030" iyy="0.000312" iyz="0.000000" izx="0.000000" izy="0.000000" izz="0.000255" />
            <!--inertia ixx="0.000003"  ixy="-0.000002" ixz="0.000000"
                 iyx="-0.000002" iyy="0.000021"  iyz="0.000000"
                 izx="0.000000"  izy="0.000000"  izz="0.000020" /-->
        </inertial>
    </link>
    <link name="robotiq_85_right_finger_link">
        <visual>
            <geometry>
                <mesh filename="package://tsuzuki_sim_description/meshes/robotiq_85_gripper/visual/robotiq_85_finger_link.dae" />
            </geometry>
        </visual>
        <collision>
            <geometry>
                <mesh filename="package://tsuzuki_sim_description/meshes/robotiq_85_gripper/collision/robotiq_85_finger_link.stl" />
            </geometry>
        </collision>
        <inertial>
            <mass value="0.027309" />
            <origin xyz="0.021401 -0.002777 0.0" rpy="0 0 0" />
            <inertia ixx="0.000086" ixy="0.000030" ixz="0.000000" iyx="0.000030" iyy="0.000312" iyz="0.000000" izx="0.000000" izy="0.000000" izz="0.000255" />
            <!--inertia ixx="0.000003"  ixy="-0.000002" ixz="0.000000"
                 iyx="-0.000002" iyy="0.000021"  iyz="0.000000"
                 izx="0.000000"  izy="0.000000"  izz="0.000020" /-->
        </inertial>
    </link>
    <joint name="robotiq_85_left_inner_knuckle_joint" type="continuous">
        <parent link="robotiq_85_base_link" />
        <child link="robotiq_85_left_inner_knuckle_link" />
        <axis xyz="0 0 1" />
        <origin rpy="3.141592653589793 0.0 0.0" xyz="0.06142 0.0127 0" />
        <limit effort="0.1" lower="-3.14" upper="3.14" velocity="100.0" />
        <dynamics damping="0.1" />
        <mimic joint="robotiq_85_left_knuckle_joint" offset="0" />
    </joint>
    <joint name="robotiq_85_right_inner_knuckle_joint" type="continuous">
        <parent link="robotiq_85_base_link" />
        <child link="robotiq_85_right_inner_knuckle_link" />
        <axis xyz="0 0 1" />
        <origin rpy="0 0 0" xyz="0.06142 -0.0127 0" />
        <limit effort="0.1" lower="-3.14" upper="3.14" velocity="100.0" />
        <dynamics damping="0.1" />
        <mimic joint="robotiq_85_left_knuckle_joint" offset="0" />
    </joint>
    <link name="robotiq_85_left_inner_knuckle_link">
        <visual>
            <geometry>
                <mesh filename="package://tsuzuki_sim_description/meshes/robotiq_85_gripper/visual/robotiq_85_inner_knuckle_link.dae" />
            </geometry>
        </visual>
        <collision>
            <geometry>
                <mesh filename="package://tsuzuki_sim_description/meshes/robotiq_85_gripper/collision/robotiq_85_inner_knuckle_link.stl" />
            </geometry>
        </collision>
        <inertial>
            <mass value="0.029951" />
            <origin xyz="0.021278 -0.018589 0.0" rpy="0 0 0" />
            <inertia ixx="0.000348" ixy="0.000184" ixz="0.000000" iyx="0.000184" iyy="0.000398" iyz="0.000000" izx="0.000000" izy="0.000000" izz="0.000396" />
            <!--inertia ixx="0.000039" ixy="0.000000" ixz="0.000000"
                 iyx="0.000000" iyy="0.000005" iyz="0.000000"
                 izx="0.000000" izy="0.000000" izz="0.000035" /-->
        </inertial>
    </link>
    <link name="robotiq_85_right_inner_knuckle_link">
        <visual>
            <geometry>
                <mesh filename="package://tsuzuki_sim_description/meshes/robotiq_85_gripper/visual/robotiq_85_inner_knuckle_link.dae" />
            </geometry>
        </visual>
        <collision>
            <geometry>
                <mesh filename="package://tsuzuki_sim_description/meshes/robotiq_85_gripper/collision/robotiq_85_inner_knuckle_link.stl" />
            </geometry>
        </collision>
        <inertial>
            <mass value="0.029951" />
            <origin xyz="0.021278 -0.018589 0.0" rpy="0 0 0" />
            <inertia ixx="0.000348" ixy="0.000184" ixz="0.000000" iyx="0.000184" iyy="0.000398" iyz="0.000000" izx="0.000000" izy="0.000000" izz="0.000396" />
            <!--inertia ixx="0.000039" ixy="0.000000" ixz="0.000000"
                 iyx="0.000000" iyy="0.000005" iyz="0.000000"
                 izx="0.000000" izy="0.000000" izz="0.000035" /-->
        </inertial>
    </link>
    <joint name="robotiq_85_left_finger_tip_joint" type="continuous">
        <parent link="robotiq_85_left_inner_knuckle_link" />
        <child link="robotiq_85_left_finger_tip_link" />
        <axis xyz="0 0 1" />
        <origin rpy="0.0 0.0 0.0" xyz="0.04303959807 -0.03759940821 0.0" />
        <limit effort="0.1" lower="-3.14" upper="3.14" velocity="100.0" />
        <dynamics damping="0.1" />
        <mimic joint="robotiq_85_left_knuckle_joint" multiplier="-1" />
    </joint>
    <joint name="robotiq_85_right_finger_tip_joint" type="continuous">
        <parent link="robotiq_85_right_inner_knuckle_link" />
        <child link="robotiq_85_right_finger_tip_link" />
        <axis xyz="0 0 1" />
        <origin rpy="0.0 0.0 0.0" xyz="0.04303959807 -0.03759940821  0.0" />
        <limit effort="0.1" lower="-3.14" upper="3.14" velocity="100.0" />
        <dynamics damping="0.1" />
        <mimic joint="robotiq_85_left_knuckle_joint" multiplier="-1" />
    </joint>
    <link name="robotiq_85_left_finger_tip_link">
        <visual>
            <geometry>
                <mesh filename="package://tsuzuki_sim_description/meshes/robotiq_85_gripper/visual/robotiq_85_finger_tip_link.dae" />
            </geometry>
        </visual>
        <collision>
            <geometry>
                <mesh filename="package://tsuzuki_sim_description/meshes/robotiq_85_gripper/collision/robotiq_85_finger_tip_link.stl" />
            </geometry>
        </collision>
        <inertial>
            <mass value="0.019555" />
            <origin xyz="0.014854 -0.001507 0.0" rpy="0 0 0" />
            <inertia ixx="0.000106" ixy="-0.000096" ixz="0.000000" iyx="-0.000096" iyy="0.000344" iyz="0.000000" izx="0.000000" izy="0.000000" izz="0.000381" />
            <!--inertia ixx="0.000002" ixy="0.000000" ixz="0.000000"
                 iyx="0.000000" iyy="0.000005" iyz="0.000000"
                 izx="0.000000" izy="0.000000" izz="0.000006" /-->
        </inertial>
    </link>
    <link name="robotiq_85_right_finger_tip_link">
        <visual>
            <geometry>
                <mesh filename="package://tsuzuki_sim_description/meshes/robotiq_85_gripper/visual/robotiq_85_finger_tip_link.dae" />
            </geometry>
        </visual>
        <collision>
            <geometry>
                <mesh filename="package://tsuzuki_sim_description/meshes/robotiq_85_gripper/collision/robotiq_85_finger_tip_link.stl" />
            </geometry>
        </collision>
        <inertial>
            <mass value="0.019555" />
            <origin xyz="0.014854 -0.001507 0.0" rpy="0 0 0" />
            <inertia ixx="0.000106" ixy="-0.000096" ixz="0.000000" iyx="-0.000096" iyy="0.000344" iyz="0.000000" izx="0.000000" izy="0.000000" izz="0.000381" />
            <!--inertia ixx="0.000002" ixy="0.000000" ixz="0.000000"
                 iyx="0.000000" iyy="0.000005" iyz="0.000000"
                 izx="0.000000" izy="0.000000" izz="0.000006" /-->
        </inertial>
    </link>
    <transmission name="robotiq_85_left_knuckle_trans">
        <type>transmission_interface/SimpleTransmission</type>
        <joint name="robotiq_85_left_knuckle_joint">
            <hardwareInterface>hardware_interface/EffortJointInterface</hardwareInterface>
            <!--hardwareInterface>hardware_interface/PositionJointInterface</hardwareInterface-->
        </joint>
        <actuator name="robotiq_85_left_knuckle_motor">
            <hardwareInterface>hardware_interface/EffortJointInterface</hardwareInterface>
            <!--hardwareInterface>hardware_interface/PositionJointInterface</hardwareInterface-->
            <mechanicalReduction>1</mechanicalReduction>
        </actuator>
    </transmission>
    <!-- Mimic joints -->
    <gazebo>
        <plugin filename="libgazebo_mimic_joint_plugin.so" name="mimic_robotiq_85_1">
            <joint>robotiq_85_left_knuckle_joint</joint>
            <mimicJoint>robotiq_85_right_knuckle_joint</mimicJoint>
        </plugin>
        <plugin filename="libgazebo_mimic_joint_plugin.so" name="mimic_robotiq_85_2">
            <joint>robotiq_85_left_knuckle_joint</joint>
            <mimicJoint>robotiq_85_left_inner_knuckle_joint</mimicJoint>
        </plugin>
        <plugin filename="libgazebo_mimic_joint_plugin.so" name="mimic_robotiq_85_3">
            <joint>robotiq_85_left_knuckle_joint</joint>
            <mimicJoint>robotiq_85_right_inner_knuckle_joint</mimicJoint>
        </plugin>
        <plugin filename="libgazebo_mimic_joint_plugin.so" name="mimic_robotiq_85_4">
            <joint>robotiq_85_left_knuckle_joint</joint>
            <mimicJoint>robotiq_85_left_finger_tip_joint</mimicJoint>
            <multiplier>-1.0</multiplier>
            <offset>0.0</offset>
        </plugin>
        <plugin filename="libgazebo_mimic_joint_plugin.so" name="mimic_robotiq_85_5">
            <joint>robotiq_85_left_knuckle_joint</joint>
            <mimicJoint>robotiq_85_right_finger_tip_joint</mimicJoint>
            <multiplier>-1.0</multiplier>
            <offset>0.0</offset>
        </plugin>
        <!--plugin filename="libgazebo_mimic_joint_plugin.so" name="${prefix}mimic_robotiq_85_6">
        <joint>${prefix}robotiq_85_left_knuckle_joint</joint>
        <mimicJoint>${prefix}tsuzuki_left_finger_tip_joint</mimicJoint>
        <multiplier>0.0</multiplier>
        <offset>0.0</offset>
      </plugin>
      <plugin filename="libgazebo_mimic_joint_plugin.so" name="${prefix}mimic_robotiq_85_7">
        <joint>${prefix}robotiq_85_left_knuckle_joint</joint>
        <mimicJoint>${prefix}tsuzuki_right_finger_tip_joint</mimicJoint>
        <multiplier>0.0</multiplier>
        <offset>0.0</offset>
      </plugin-->
    </gazebo>
    <!-- The following are additions by nosaka and yamakawa -->
    <!-- add finger destination by yamakawa -->
    <link name="ur5_gripper_link" />
    <joint name="ur5_gripper_joint" type="fixed">
        <parent link="robotiq_85_base_link" />
        <child link="ur5_gripper_link" />
        <origin rpy="0 -1.5707963267948966 0" xyz="0.205 0 0" />
        <axis xyz="1 0 0" />
    </joint>
    <!-- add tsuzuki_finger_tip by nosaka -->
    <!-- left tip -->
    <link name="tsuzuki_left_finger_tip_link">
        <visual>
            <geometry>
                <mesh filename="package://tsuzuki_sim_description/meshes/tsuzuki_finger/new_finger.stl" scale="0.001 0.001 0.001" />
            </geometry>
            <material name="gray">
                <color rgba="0.8 0.8 0.8 1" />
            </material>
        </visual>
        <collision>
            <geometry>
                <mesh filename="package://tsuzuki_sim_description/meshes/tsuzuki_finger/new_finger.stl" scale="0.001 0.001 0.001" />
            </geometry>
        </collision>
        <!-- interia check -->
        <inertial>
            <mass value="0.057" />
            <origin xyz="0.0 0.0056495 0.0307566" rpy="0 0 0" />
            <inertia ixx="0.001112" ixy="0.000000" ixz="0.000000" iyx="0.000000" iyy="0.001189" iyz="0.000065" izx="0.000000" izy="0.000065" izz="0.000131" />
            <!--inertia ixx="0.000002" ixy="0.000000" ixz="0.000000"
                 iyx="0.000000" iyy="0.000005" iyz="0.000000"
                 izx="0.000000" izy="0.000000" izz="0.000006" /-->
        </inertial>
    </link>
    <joint name="tsuzuki_left_finger_tip_joint" type="fixed">
        <parent link="robotiq_85_left_finger_tip_link" />
        <child link="tsuzuki_left_finger_tip_link" />
        <origin rpy="3.141592653589793 1.5707963267948966 0" xyz="0.091 0.008 0" />
        <axis xyz="0 0 0" />
        <!--limit lower="-3.14" upper="3.14" velocity="100.0" effort="0.1"/>
      <mimic joint="${prefix}robotiq_85_left_knuckle_joint" multiplier="0"/-->
    </joint>
    <!-- right tip -->
    <link name="tsuzuki_right_finger_tip_link">
        <visual>
            <geometry>
                <mesh filename="package://tsuzuki_sim_description/meshes/tsuzuki_finger/new_finger.stl" scale="0.001 0.001 0.001" />
            </geometry>
            <material name="gray">
                <color rgba="0.8 0.8 0.8 1" />
            </material>
        </visual>
        <collision>
            <geometry>
                <mesh filename="package://tsuzuki_sim_description/meshes/tsuzuki_finger/new_finger.stl" scale="0.001 0.001 0.001" />
            </geometry>
        </collision>
        <!-- interia check -->
        <inertial>
            <mass value="0.057" />
            <origin xyz="0.0 0.0056495 0.0307566" rpy="0 0 0" />
            <inertia ixx="0.001112" ixy="0.000000" ixz="0.000000" iyx="0.000000" iyy="0.001189" iyz="0.000065" izx="0.000000" izy="0.000065" izz="0.000131" />
            <!--inertia ixx="0.000002" ixy="0.000000" ixz="0.000000"
                 iyx="0.000000" iyy="0.000005" iyz="0.000000"
                 izx="0.000000" izy="0.000000" izz="0.000006" /-->
        </inertial>
    </link>
    <joint name="tsuzuki_right_finger_tip_joint" type="fixed">
        <parent link="robotiq_85_right_finger_tip_link" />
        <child link="tsuzuki_right_finger_tip_link" />
        <origin rpy="3.141592653589793 1.5707963267948966 0" xyz="0.091 0.008 0" />
        <axis xyz="0 0 0" />
        <!--limit lower="-3.14" upper="3.14" velocity="100.0" effort="0.1"/>
      <mimic joint="${prefix}robotiq_85_left_knuckle_joint" multiplier="0"/-->
    </joint>
    <link name="world" />
    <!-- setup robot's pedestal -->
    <link name="pedestal_link">
        <visual>
            <origin rpy="0 0 0" xyz="0 0 0.2775" />
            <geometry>
                <cylinder length="0.555" radius="0.1" />
            </geometry>
            <material name="gray">
                <color rgba="0.5 0.5 0.5 0" />
            </material>
        </visual>
        <collision>
            <origin rpy="0 0 0" xyz="0 0 0.2775" />
            <geometry>
                <cylinder length="0.555" radius="0.1" />
            </geometry>
        </collision>
        <inertial>
            <origin rpy="0 0 0" xyz="0 0 0.2775" />
            <mass value="20" />
            <inertia ixx="200" ixy="200" ixz="200" iyy="200" iyz="200" izz="200" />
        </inertial>
    </link>
    <joint name="pedestal_joint" type="fixed">
        <parent link="world" />
        <child link="pedestal_link" />
        <origin rpy="0.0 0.0 0.0" xyz="0.0 0.0 0.0" />
    </joint>
    <joint name="base_joint" type="fixed">
        <parent link="pedestal_link" />
        <child link="base_link" />
        <origin rpy="0.0 0.0 -0.7853981633974483" xyz="0.0 0.0 0.555" />
    </joint>
    <!-- setup ensenso_n35 -->
    <joint name="ensenso_joint" type="fixed">
        <parent link="world" />
        <child link="ensenso_world" />
        <!--origin xyz="0.56 -0.035 1.605" rpy="${-pi} 0.0 ${pi/2.0}" /-->
        <origin rpy="-3.141592653589793 0.0 1.5707963267948966" xyz="0.56 0.0 1.65" />
    </joint>
    <!-- setup robotiq_coupler -->
    <!--  + Height added by the coupler: 8mm
        + Reference frame: at the middle (4mm) -->
    <link name="robotiq_coupler">
        <visual>
            <geometry>
                <mesh filename="package://tsuzuki_sim_description/meshes/robotiq_85_gripper/robotiq_85_coupler.stl" />
            </geometry>
            <material name="flat_black">
                <color rgba="0.2 0.2 0.2 1" />
            </material>
        </visual>
        <collision>
            <geometry>
                <mesh filename="package://tsuzuki_sim_description/meshes/robotiq_85_gripper/robotiq_85_coupler.stl" />
            </geometry>
        </collision>
        <inertial>
            <origin rpy="0 0 0" xyz="2.073e-05   1.45286e-03  -1.1049e-03" />
            <mass value="0.168" />
            <inertia ixx="6.69695624e-05" ixy="5.21511788e-09" ixz="-2.74383009e-08" iyy="7.85088161e-05" iyz="5.41105193e-07" izz="1.41819717e-04" />
        </inertial>
    </link>
    <joint name="robotiq_coupler_joint" type="fixed">
        <!--origin xyz="0 0 0.008" rpy="0 0 ${-pi/2.0}" /-->
        <origin rpy="0 0 -1.5707963267948966" xyz="0 0 0.005" />
        <parent link="tool0" />
        <child link="robotiq_coupler" />
    </joint>
    <transmission name="trans_robotiq_85_right_knuckle_joint">
        <type>transmission_interface/SimpleTransmission</type>
        <joint name="robotiq_85_right_knuckle_joint">
            <hardwareInterface>hardware_interface/EffortJointInterface</hardwareInterface>
        </joint>
        <actuator name="robotiq_85_right_knuckle_joint_motor">
            <hardwareInterface>hardware_interface/EffortJointInterface</hardwareInterface>
            <mechanicalReduction>1</mechanicalReduction>
        </actuator>
    </transmission>
    <transmission name="trans_robotiq_85_left_inner_knuckle_joint">
        <type>transmission_interface/SimpleTransmission</type>
        <joint name="robotiq_85_left_inner_knuckle_joint">
            <hardwareInterface>hardware_interface/EffortJointInterface</hardwareInterface>
        </joint>
        <actuator name="robotiq_85_left_inner_knuckle_joint_motor">
            <hardwareInterface>hardware_interface/EffortJointInterface</hardwareInterface>
            <mechanicalReduction>1</mechanicalReduction>
        </actuator>
    </transmission>
    <transmission name="trans_robotiq_85_right_inner_knuckle_joint">
        <type>transmission_interface/SimpleTransmission</type>
        <joint name="robotiq_85_right_inner_knuckle_joint">
            <hardwareInterface>hardware_interface/EffortJointInterface</hardwareInterface>
        </joint>
        <actuator name="robotiq_85_right_inner_knuckle_joint_motor">
            <hardwareInterface>hardware_interface/EffortJointInterface</hardwareInterface>
            <mechanicalReduction>1</mechanicalReduction>
        </actuator>
    </transmission>
    <transmission name="trans_robotiq_85_left_finger_tip_joint">
        <type>transmission_interface/SimpleTransmission</type>
        <joint name="robotiq_85_left_finger_tip_joint">
            <hardwareInterface>hardware_interface/EffortJointInterface</hardwareInterface>
        </joint>
        <actuator name="robotiq_85_left_finger_tip_joint_motor">
            <hardwareInterface>hardware_interface/EffortJointInterface</hardwareInterface>
            <mechanicalReduction>1</mechanicalReduction>
        </actuator>
    </transmission>
    <transmission name="trans_robotiq_85_right_finger_tip_joint">
        <type>transmission_interface/SimpleTransmission</type>
        <joint name="robotiq_85_right_finger_tip_joint">
            <hardwareInterface>hardware_interface/EffortJointInterface</hardwareInterface>
        </joint>
        <actuator name="robotiq_85_right_finger_tip_joint_motor">
            <hardwareInterface>hardware_interface/EffortJointInterface</hardwareInterface>
            <mechanicalReduction>1</mechanicalReduction>
        </actuator>
    </transmission>
</robot>

